<?xml version="1.0" ?>

<robot name="onedof">
	<link name="base_link" />

	<link name="link1">
		<inertial>
	      <origin rpy="0 0 0" xyz="0 0 0"/>
	      <mass value="1"/>
	      <inertia ixx="0.085833" ixy="0" ixz="0" iyy="0.085833" iyz="0" izz="0.005"/>
	    </inertial>
		<visual>
		  <geometry>
				<cylinder radius="0.1" length="1.0"/>
		  </geometry>
		  <origin rpy="0 0 0" xyz="0 0 0"/>
		</visual>
	</link>

	<link name="link2">
		<inertial>
	      <origin rpy="0 0 0" xyz="0 0 0.5"/>
	      <mass value="1"/>
	      <inertia ixx="0.085833" ixy="0" ixz="0" iyy="0.085833" iyz="0" izz="0.005"/>
	    </inertial>
		<visual>
		  <geometry>
				<cylinder radius="0.1" length="1.0"/>
			</geometry>
		  <origin rpy="0 0 0" xyz="0 0 0.5"/>
		</visual>
	</link>

	<joint name="base" type="fixed">
		<parent link="base_link"/>
		<child link="link1"/>
		<origin rpy="0 0 0" xyz="0 0 0.5"/>
	</joint>

	<joint name="joint" type="revolute">
		<parent link="link1"/>
		<child link="link2"/>
		<origin rpy="0 3.14159 0" xyz="0 0 0.5"/>
		<axis xyz="0 1 0" />
		<limit effort="3" lower="-1.57" upper="1.57" velocity="1"/>
	</joint>
</robot>
